Workbook

Sheet Datos
A1: Datos crudos de Ct y cálculo por pocillo (ΔΔCt, housekeeping YWHAZ)
A2: Columna E (azul) = 1 incluye el pocillo, 0 lo excluye. Cámbiala y todo se recalcula. Criterio de exclusión: SD del triplicado > 0,3 Ct → se quita el punto que más reduce la SD (máx. 1 por triplicado).
A4: Pocillo | B4: Muestra | C4: Gen | D4: Ct | E4: Incluir (1/0) | F4: Motivo exclusión | G4: Control | H4: Ct medio YWHAZ (muestra) | I4: ΔCt | J4: ΔCt medio control | K4: RQ (2^-ΔΔCt) | L4: RQ²
A5: B4 | B5: KerCT 0 días MD2 | C5: YWHAZ | D5: 16.511551 | E5: 1 | G5: =INDEX(Controles!$B$5:$B$9,MATCH(B5,Controles!$A$5:$A$9,0)) | H5: =AVERAGEIFS($D$5:$D$94,$B$5:$B$94,B5,$C$5:$C$94,"YWHAZ",$E$5:$E$94,1)
A6: B5 | B6: KerCT 0 días MD2 | C6: YWHAZ | D6: 16.290541 | E6: 1 | G6: =INDEX(Controles!$B$5:$B$9,MATCH(B6,Controles!$A$5:$A$9,0)) | H6: =AVERAGEIFS($D$5:$D$94,$B$5:$B$94,B6,$C$5:$C$94,"YWHAZ",$E$5:$E$94,1)
A7: B6 | B7: KerCT 0 días MD2 | C7: YWHAZ | D7: 16.589418 | E7: 1 | G7: =INDEX(Controles!$B$5:$B$9,MATCH(B7,Controles!$A$5:$A$9,0)) | H7: =AVERAGEIFS($D$5:$D$94,$B$5:$B$94,B7,$C$5:$C$94,"YWHAZ",$E$5:$E$94,1)
A8: A1 | B8: KerCT 0 días MD2 | C8: KRT1 | D8: 32.450451 | E8: 1 | G8: =INDEX(Controles!$B$5:$B$9,MATCH(B8,Controles!$A$5:$A$9,0)) | H8: =AVERAGEIFS($D$5:$D$94,$B$5:$B$94,B8,$C$5:$C$94,"YWHAZ",$E$5:$E$94,1) | I8: =D8-H8 | J8: =AVERAGEIFS($I$5:$I$94,$B$5:$B$94,G8,$C$5:$C$94,C8,$E$5:$E$94,1) | K8: =IF(E8=1,2^-(I8-J8),"") | L8: =IF(E8=1,K8*K8,0)
A9: A2 | B9: KerCT 0 días MD2 | C9: KRT1 | D9: 31.178719 | E9: 0 | F9: Fuera de la media: SD triplicado 0.78 → 0.10 Ct al quitarlo | G9: =INDEX(Controles!$B$5:$B$9,MATCH(B9,Controles!$A$5:$A$9,0)) | H9: =AVERAGEIFS($D$5:$D$94,$B$5:$B$94,B9,$C$5:$C$94,"YWHAZ",$E$5:$E$94,1) | I9: =D9-H9 | J9: =AVERAGEIFS($I$5:$I$94,$B$5:$B$94,G9,$C$5:$C$94,C9,$E$5:$E$94,1) | K9: =IF(E9=1,2^-(I9-J9),"") | L9: =IF(E9=1,K9*K9,0)
A10: A3 | B10: KerCT 0 días MD2 | C10: KRT1 | D10: 32.58997 | E10: 1 | G10: =INDEX(Controles!$B$5:$B$9,MATCH(B10,Controles!$A$5:$A$9,0)) | H10: =AVERAGEIFS($D$5:$D$94,$B$5:$B$94,B10,$C$5:$C$94,"YWHAZ",$E$5:$E$94,1) | I10: =D10-H10 | J10: =AVERAGEIFS($I$5:$I$94,$B$5:$B$94,G10,$C$5:$C$94,C10,$E$5:$E$94,1) | K10: =IF(E10=1,2^-(I10-J10),"") | L10: =IF(E10=1,K10*K10,0)
A11: A7 | B11: KerCT 0 días MD2 | C11: KRT2 | D11: 31.741945 | E11: 1 | G11: =INDEX(Controles!$B$5:$B$9,MATCH(B11,Controles!$A$5:$A$9,0)) | H11: =AVERAGEIFS($D$5:$D$94,$B$5:$B$94,B11,$C$5:$C$94,"YWHAZ",$E$5:$E$94,1) | I11: =D11-H11 | J11: =AVERAGEIFS($I$5:$I$94,$B$5:$B$94,G11,$C$5:$C$94,C11,$E$5:$E$94,1) | K11: =IF(E11=1,2^-(I11-J11),"") | L11: =IF(E11=1,K11*K11,0)
A12: A8 | B12: KerCT 0 días MD2 | C12: KRT2 | D12: 31.546152 | E12: 1 | G12: =INDEX(Controles!$B$5:$B$9,MATCH(B12,Controles!$A$5:$A$9,0)) | H12: =AVERAGEIFS($D$5:$D$94,$B$5:$B$94,B12,$C$5:$C$94,"YWHAZ",$E$5:$E$94,1) | I12: =D12-H12 | J12: =AVERAGEIFS($I$5:$I$94,$B$5:$B$94,G12,$C$5:$C$94,C12,$E$5:$E$94,1) | K12: =IF(E12=1,2^-(I12-J12),"") | L12: =IF(E12=1,K12*K12,0)
A13: A9 | B13: KerCT 0 días MD2 | C13: KRT2 | D13: 31.304642 | E13: 1 | G13: =INDEX(Controles!$B$5:$B$9,MATCH(B13,Controles!$A$5:$A$9,0)) | H13: =AVERAGEIFS($D$5:$D$94,$B$5:$B$94,B13,$C$5:$C$94,"YWHAZ",$E$5:$E$94,1) | I13: =D13-H13 | J13: =AVERAGEIFS($I$5:$I$94,$B$5:$B$94,G13,$C$5:$C$94,C13,$E$5:$E$94,1) | K13: =IF(E13=1,2^-(I13-J13),"") | L13: =IF(E13=1,K13*K13,0)
A14: A4 | B14: KerCT 0 días MD2 | C14: KRT10 | D14: 20.470182 | E14: 1 | G14: =INDEX(Controles!$B$5:$B$9,MATCH(B14,Controles!$A$5:$A$9,0)) | H14: =AVERAGEIFS($D$5:$D$94,$B$5:$B$94,B14,$C$5:$C$94,"YWHAZ",$E$5:$E$94,1) | I14: =D14-H14 | J14: =AVERAGEIFS($I$5:$I$94,$B$5:$B$94,G14,$C$5:$C$94,C14,$E$5:$E$94,1) | K14: =IF(E14=1,2^-(I14-J14),"") | L14: =IF(E14=1,K14*K14,0)
A15: A5 | B15: KerCT 0 días MD2 | C15: KRT10 | D15: 20.496174 | E15: 1 | G15: =INDEX(Controles!$B$5:$B$9,MATCH(B15,Controles!$A$5:$A$9,0)) | H15: =AVERAGEIFS($D$5:$D$94,$B$5:$B$94,B15,$C$5:$C$94,"YWHAZ",$E$5:$E$94,1) | I15: =D15-H15 | J15: =AVERAGEIFS($I$5:$I$94,$B$5:$B$94,G15,$C$5:$C$94,C15,$E$5:$E$94,1) | K15: =IF(E15=1,2^-(I15-J15),"") | L15: =IF(E15=1,K15*K15,0)
A16: A6 | B16: KerCT 0 días MD2 | C16: KRT10 | D16: 20.619497 | E16: 1 | G16: =INDEX(Controles!$B$5:$B$9,MATCH(B16,Controles!$A$5:$A$9,0)) | H16: =AVERAGEIFS($D$5:$D$94,$B$5:$B$94,B16,$C$5:$C$94,"YWHAZ",$E$5:$E$94,1) | I16: =D16-H16 | J16: =AVERAGEIFS($I$5:$I$94,$B$5:$B$94,G16,$C$5:$C$94,C16,$E$5:$E$94,1) | K16: =IF(E16=1,2^-(I16-J16),"") | L16: =IF(E16=1,K16*K16,0)
A17: A12 | B17: KerCT 0 días MD2 | C17: KRT14 | D17: 19.840441 | E17: 1 | G17: =INDEX(Controles!$B$5:$B$9,MATCH(B17,Controles!$A$5:$A$9,0)) | H17: =AVERAGEIFS($D$5:$D$94,$B$5:$B$94,B17,$C$5:$C$94,"YWHAZ",$E$5:$E$94,1) | I17: =D17-H17 | J17: =AVERAGEIFS($I$5:$I$94,$B$5:$B$94,G17,$C$5:$C$94,C17,$E$5:$E$94,1) | K17: =IF(E17=1,2^-(I17-J17),"") | L17: =IF(E17=1,K17*K17,0)
A18: B12 | B18: KerCT 0 días MD2 | C18: KRT14 | D18: 19.867241 | E18: 1 | G18: =INDEX(Controles!$B$5:$B$9,MATCH(B18,Controles!$A$5:$A$9,0)) | H18: =AVERAGEIFS($D$5:$D$94,$B$5:$B$94,B18,$C$5:$C$94,"YWHAZ",$E$5:$E$94,1) | I18: =D18-H18 | J18: =AVERAGEIFS($I$5:$I$94,$B$5:$B$94,G18,$C$5:$C$94,C18,$E$5:$E$94,1) | K18: =IF(E18=1,2^-(I18-J18),"") | L18: =IF(E18=1,K18*K18,0)
A19: C12 | B19: KerCT 0 días MD2 | C19: KRT14 | D19: 19.531914 | E19: 1 | G19: =INDEX(Controles!$B$5:$B$9,MATCH(B19,Controles!$A$5:$A$9,0)) | H19: =AVERAGEIFS($D$5:$D$94,$B$5:$B$94,B19,$C$5:$C$94,"YWHAZ",$E$5:$E$94,1) | I19: =D19-H19 | J19: =AVERAGEIFS($I$5:$I$94,$B$5:$B$94,G19,$C$5:$C$94,C19,$E$5:$E$94,1) | K19: =IF(E19=1,2^-(I19-J19),"") | L19: =IF(E19=1,K19*K19,0)
A20: B1 | B20: KerCT 0 días MD2 | C20: IVL | D20: 27.427208 | E20: 0 | F20: Fuera de la media: SD triplicado 0.73 → 0.31 Ct al quitarlo | G20: =INDEX(Controles!$B$5:$B$9,MATCH(B20,Controles!$A$5:$A$9,0)) | H20: =AVERAGEIFS($D$5:$D$94,$B$5:$B$94,B20,$C$5:$C$94,"YWHAZ",$E$5:$E$94,1) | I20: =D20-H20 | J20: =AVERAGEIFS($I$5:$I$94,$B$5:$B$94,G20,$C$5:$C$94,C20,$E$5:$E$94,1) | K20: =IF(E20=1,2^-(I20-J20),"") | L20: =IF(E20=1,K20*K20,0)
A21: B2 | B21: KerCT 0 días MD2 | C21: IVL | D21: 26.000309 | E21: 1 | G21: =INDEX(Controles!$B$5:$B$9,MATCH(B21,Controles!$A$5:$A$9,0)) | H21: =AVERAGEIFS($D$5:$D$94,$B$5:$B$94,B21,$C$5:$C$94,"YWHAZ",$E$5:$E$94,1) | I21: =D21-H21 | J21: =AVERAGEIFS($I$5:$I$94,$B$5:$B$94,G21,$C$5:$C$94,C21,$E$5:$E$94,1) | K21: =IF(E21=1,2^-(I21-J21),"") | L21: =IF(E21=1,K21*K21,0)
A22: B3 | B22: KerCT 0 días MD2 | C22: IVL | D22: 26.444395 | E22: 1 | G22: =INDEX(Controles!$B$5:$B$9,MATCH(B22,Controles!$A$5:$A$9,0)) | H22: =AVERAGEIFS($D$5:$D$94,$B$5:$B$94,B22,$C$5:$C$94,"YWHAZ",$E$5:$E$94,1) | I22: =D22-H22 | J22: =AVERAGEIFS($I$5:$I$94,$B$5:$B$94,G22,$C$5:$C$94,C22,$E$5:$E$94,1) | K22: =IF(E22=1,2^-(I22-J22),"") | L22: =IF(E22=1,K22*K22,0)
A23: D4 | B23: KerCT 7 días MD2 1 | C23: YWHAZ | D23: 15.993332 | E23: 1 | G23: =INDEX(Controles!$B$5:$B$9,MATCH(B23,Controles!$A$5:$A$9,0)) | H23: =AVERAGEIFS($D$5:$D$94,$B$5:$B$94,B23,$C$5:$C$94,"YWHAZ",$E$5:$E$94,1)
A24: D5 | B24: KerCT 7 días MD2 1 | C24: YWHAZ | D24: 16.12093 | E24: 1 | G24: =INDEX(Controles!$B$5:$B$9,MATCH(B24,Controles!$A$5:$A$9,0)) | H24: =AVERAGEIFS($D$5:$D$94,$B$5:$B$94,B24,$C$5:$C$94,"YWHAZ",$E$5:$E$94,1)
A25: D6 | B25: KerCT 7 días MD2 1 | C25: YWHAZ | D25: 16.11153 | E25: 1 | G25: =INDEX(Controles!$B$5:$B$9,MATCH(B25,Controles!$A$5:$A$9,0)) | H25: =AVERAGEIFS($D$5:$D$94,$B$5:$B$94,B25,$C$5:$C$94,"YWHAZ",$E$5:$E$94,1)
A26: C1 | B26: KerCT 7 días MD2 1 | C26: KRT1 | D26: 26.064104 | E26: 1 | G26: =INDEX(Controles!$B$5:$B$9,MATCH(B26,Controles!$A$5:$A$9,0)) | H26: =AVERAGEIFS($D$5:$D$94,$B$5:$B$94,B26,$C$5:$C$94,"YWHAZ",$E$5:$E$94,1) | I26: =D26-H26 | J26: =AVERAGEIFS($I$5:$I$94,$B$5:$B$94,G26,$C$5:$C$94,C26,$E$5:$E$94,1) | K26: =IF(E26=1,2^-(I26-J26),"") | L26: =IF(E26=1,K26*K26,0)
A27: C2 | B27: KerCT 7 días MD2 1 | C27: KRT1 | D27: 26.184549 | E27: 1 | G27: =INDEX(Controles!$B$5:$B$9,MATCH(B27,Controles!$A$5:$A$9,0)) | H27: =AVERAGEIFS($D$5:$D$94,$B$5:$B$94,B27,$C$5:$C$94,"YWHAZ",$E$5:$E$94,1) | I27: =D27-H27 | J27: =AVERAGEIFS($I$5:$I$94,$B$5:$B$94,G27,$C$5:$C$94,C27,$E$5:$E$94,1) | K27: =IF(E27=1,2^-(I27-J27),"") | L27: =IF(E27=1,K27*K27,0)
A28: C3 | B28: KerCT 7 días MD2 1 | C28: KRT1 | D28: 25.861631 | E28: 1 | G28: =INDEX(Controles!$B$5:$B$9,MATCH(B28,Controles!$A$5:$A$9,0)) | H28: =AVERAGEIFS($D$5:$D$94,$B$5:$B$94,B28,$C$5:$C$94,"YWHAZ",$E$5:$E$94,1) | I28: =D28-H28 | J28: =AVERAGEIFS($I$5:$I$94,$B$5:$B$94,G28,$C$5:$C$94,C28,$E$5:$E$94,1) | K28: =IF(E28=1,2^-(I28-J28),"") | L28: =IF(E28=1,K28*K28,0)
A29: C7 | B29: KerCT 7 días MD2 1 | C29: KRT2 | D29: 29.779129 | E29: 1 | G29: =INDEX(Controles!$B$5:$B$9,MATCH(B29,Controles!$A$5:$A$9,0)) | H29: =AVERAGEIFS($D$5:$D$94,$B$5:$B$94,B29,$C$5:$C$94,"YWHAZ",$E$5:$E$94,1) | I29: =D29-H29 | J29: =AVERAGEIFS($I$5:$I$94,$B$5:$B$94,G29,$C$5:$C$94,C29,$E$5:$E$94,1) | K29: =IF(E29=1,2^-(I29-J29),"") | L29: =IF(E29=1,K29*K29,0)
A30: C8 | B30: KerCT 7 días MD2 1 | C30: KRT2 | D30: 29.914885 | E30: 1 | G30: =INDEX(Controles!$B$5:$B$9,MATCH(B30,Controles!$A$5:$A$9,0)) | H30: =AVERAGEIFS($D$5:$D$94,$B$5:$B$94,B30,$C$5:$C$94,"YWHAZ",$E$5:$E$94,1) | I30: =D30-H30 | J30: =AVERAGEIFS($I$5:$I$94,$B$5:$B$94,G30,$C$5:$C$94,C30,$E$5:$E$94,1) | K30: =IF(E30=1,2^-(I30-J30),"") | L30: =IF(E30=1,K30*K30,0)
A31: C9 | B31: KerCT 7 días MD2 1 | C31: KRT2 | D31: 29.795265 | E31: 1 | G31: =INDEX(Controles!$B$5:$B$9,MATCH(B31,Controles!$A$5:$A$9,0)) | H31: =AVERAGEIFS($D$5:$D$94,$B$5:$B$94,B31,$C$5:$C$94,"YWHAZ",$E$5:$E$94,1) | I31: =D31-H31 | J31: =AVERAGEIFS($I$5:$I$94,$B$5:$B$94,G31,$C$5:$C$94,C31,$E$5:$E$94,1) | K31: =IF(E31=1,2^-(I31-J31),"") | L31: =IF(E31=1,K31*K31,0)
A32: C4 | B32: KerCT 7 días MD2 1 | C32: KRT10 | D32: 15.543039 | E32: 1 | G32: =INDEX(Controles!$B$5:$B$9,MATCH(B32,Controles!$A$5:$A$9,0)) | H32: =AVERAGEIFS($D$5:$D$94,$B$5:$B$94,B32,$C$5:$C$94,"YWHAZ",$E$5:$E$94,1) | I32: =D32-H32 | J32: =AVERAGEIFS($I$5:$I$94,$B$5:$B$94,G32,$C$5:$C$94,C32,$E$5:$E$94,1) | K32: =IF(E32=1,2^-(I32-J32),"") | L32: =IF(E32=1,K32*K32,0)
A33: C5 | B33: KerCT 7 días MD2 1 | C33: KRT10 | D33: 15.51081 | E33: 1 | G33: =INDEX(Controles!$B$5:$B$9,MATCH(B33,Controles!$A$5:$A$9,0)) | H33: =AVERAGEIFS($D$5:$D$94,$B$5:$B$94,B33,$C$5:$C$94,"YWHAZ",$E$5:$E$94,1) | I33: =D33-H33 | J33: =AVERAGEIFS($I$5:$I$94,$B$5:$B$94,G33,$C$5:$C$94,C33,$E$5:$E$94,1) | K33: =IF(E33=1,2^-(I33-J33),"") | L33: =IF(E33=1,K33*K33,0)
A34: C6 | B34: KerCT 7 días MD2 1 | C34: KRT10 | D34: 15.513896 | E34: 1 | G34: =INDEX(Controles!$B$5:$B$9,MATCH(B34,Controles!$A$5:$A$9,0)) | H34: =AVERAGEIFS($D$5:$D$94,$B$5:$B$94,B34,$C$5:$C$94,"YWHAZ",$E$5:$E$94,1) | I34: =D34-H34 | J34: =AVERAGEIFS($I$5:$I$94,$B$5:$B$94,G34,$C$5:$C$94,C34,$E$5:$E$94,1) | K34: =IF(E34=1,2^-(I34-J34),"") | L34: =IF(E34=1,K34*K34,0)
A35: D12 | B35: KerCT 7 días MD2 1 | C35: KRT14 | D35: 20.926746 | E35: 1 | G35: =INDEX(Controles!$B$5:$B$9,MATCH(B35,Controles!$A$5:$A$9,0)) | H35: =AVERAGEIFS($D$5:$D$94,$B$5:$B$94,B35,$C$5:$C$94,"YWHAZ",$E$5:$E$94,1) | I35: =D35-H35 | J35: =AVERAGEIFS($I$5:$I$94,$B$5:$B$94,G35,$C$5:$C$94,C35,$E$5:$E$94,1) | K35: =IF(E35=1,2^-(I35-J35),"") | L35: =IF(E35=1,K35*K35,0)
A36: E12 | B36: KerCT 7 días MD2 1 | C36: KRT14 | D36: 21.114927 | E36: 1 | G36: =INDEX(Controles!$B$5:$B$9,MATCH(B36,Controles!$A$5:$A$9,0)) | H36: =AVERAGEIFS($D$5:$D$94,$B$5:$B$94,B36,$C$5:$C$94,"YWHAZ",$E$5:$E$94,1) | I36: =D36-H36 | J36: =AVERAGEIFS($I$5:$I$94,$B$5:$B$94,G36,$C$5:$C$94,C36,$E$5:$E$94,1) | K36: =IF(E36=1,2^-(I36-J36),"") | L36: =IF(E36=1,K36*K36,0)
A37: F12 | B37: KerCT 7 días MD2 1 | C37: KRT14 | D37: 20.611078 | E37: 1 | G37: =INDEX(Controles!$B$5:$B$9,MATCH(B37,Controles!$A$5:$A$9,0)) | H37: =AVERAGEIFS($D$5:$D$94,$B$5:$B$94,B37,$C$5:$C$94,"YWHAZ",$E$5:$E$94,1) | I37: =D37-H37 | J37: =AVERAGEIFS($I$5:$I$94,$B$5:$B$94,G37,$C$5:$C$94,C37,$E$5:$E$94,1) | K37: =IF(E37=1,2^-(I37-J37),"") | L37: =IF(E37=1,K37*K37,0)
... A40: D3 | B40: KerCT 7 días MD2 1 | C40: IVL | D40: 18.293165 | E40: 1 | G40: =INDEX(Controles!$B$5:$B$9,MATCH(B40,Controles!$A$5:$A$9,0)) | H40: =AVERAGEIFS($D$5:$D$94,$B$5:$B$94,B40,$C$5:$C$94,"YWHAZ",$E$5:$E$94,1) | I40: =D40-H40 | J40: =AVERAGEIFS($I$5:$I$94,$B$5:$B$94,G40,$C$5:$C$94,C40,$E$5:$E$94,1) | K40: =IF(E40=1,2^-(I40-J40),"") | L40: =IF(E40=1,K40*K40,0)
A41: F4 | B41: KerCT 7 días MD2 2 | C41: YWHAZ | D41: 15.912889 | E41: 1 | G41: =INDEX(Controles!$B$5:$B$9,MATCH(B41,Controles!$A$5:$A$9,0)) | H41: =AVERAGEIFS($D$5:$D$94,$B$5:$B$94,B41,$C$5:$C$94,"YWHAZ",$E$5:$E$94,1)
A42: F5 | B42: KerCT 7 días MD2 2 | C42: YWHAZ | D42: 15.994137 | E42: 1 | G42: =INDEX(Controles!$B$5:$B$9,MATCH(B42,Controles!$A$5:$A$9,0)) | H42: =AVERAGEIFS($D$5:$D$94,$B$5:$B$94,B42,$C$5:$C$94,"YWHAZ",$E$5:$E$94,1)
A43: F6 | B43: KerCT 7 días MD2 2 | C43: YWHAZ | D43: 15.998521 | E43: 1 | G43: =INDEX(Controles!$B$5:$B$9,MATCH(B43,Controles!$A$5:$A$9,0)) | H43: =AVERAGEIFS($D$5:$D$94,$B$5:$B$94,B43,$C$5:$C$94,"YWHAZ",$E$5:$E$94,1)
...

Sheet Controles
A1: Línea control de cada muestra
A2: Indicado por el usuario (azul = editable).
A4: Muestra | B4: Control
A5: KerCT 0 días MD2 | B5: KerCT 0 días MD2
A6: KerCT 7 días MD2 1 | B6: KerCT 0 días MD2
A7: KerCT 7 días MD2 2 | B7: KerCT 0 días MD2
A8: KerCT 0 días MD3 | B8: KerCT 0 días MD3
A9: KerCT 7 días MD3 | B9: KerCT 0 días MD3

Sheet Resumen
A1: Resumen: expresión relativa (RQ) media ± SD de las réplicas incluidas
A3: Muestra | B3: Gen | C3: Control | D3: n | E3: RQ media | F3: SD | G3: Nota | I3: MD2 – RQ media
A4: KerCT 0 días MD2 | B4: KRT1 | C4: =INDEX(Controles!$B$5:$B$9,MATCH(A4,Controles!$A$5:$A$9,0)) | D4: =COUNTIFS(Datos!$B$5:$B$94,$A4,Datos!$C$5:$C$94,$B4,Datos!$E$5:$E$94,1) | E4: =AVERAGEIFS(Datos!$K$5:$K$94,Datos!$B$5:$B$94,$A4,Datos!$C$5:$C$94,$B4,Datos!$E$5:$E$94,1) | F4: =IF(D4>1,SQRT(MAX(0,(SUMIFS(Datos!$L$5:$L$94,Datos!$B$5:$B$94,$A4,Datos!$C$5:$C$94,$B4,Datos!$E$5:$E$94,1)-D4*E4^2)/(D4-1))),0) | G4: =IF(D4<3,"duplicado","") | I4: Gen | J4: KerCT 0 días MD2 | K4: KerCT 7 días MD2 1 | L4: KerCT 7 días MD2 2
A5: KerCT 0 días MD2 | B5: KRT2 | C5: =INDEX(Controles!$B$5:$B$9,MATCH(A5,Controles!$A$5:$A$9,0)) | D5: =COUNTIFS(Datos!$B$5:$B$94,$A5,Datos!$C$5:$C$94,$B5,Datos!$E$5:$E$94,1) | E5: =AVERAGEIFS(Datos!$K$5:$K$94,Datos!$B$5:$B$94,$A5,Datos!$C$5:$C$94,$B5,Datos!$E$5:$E$94,1) | F5: =IF(D5>1,SQRT(MAX(0,(SUMIFS(Datos!$L$5:$L$94,Datos!$B$5:$B$94,$A5,Datos!$C$5:$C$94,$B5,Datos!$E$5:$E$94,1)-D5*E5^2)/(D5-1))),0) | G5: =IF(D5<3,"duplicado","") | I5: KRT1 | J5: =SUMIFS($E$4:$E$28,$A$4:$A$28,J4,$B$4:$B$28,$I5) | K5: =SUMIFS($E$4:$E$28,$A$4:$A$28,K4,$B$4:$B$28,$I5) | L5: =SUMIFS($E$4:$E$28,$A$4:$A$28,L4,$B$4:$B$28,$I5)
A6: KerCT 0 días MD2 | B6: KRT10 | C6: =INDEX(Controles!$B$5:$B$9,MATCH(A6,Controles!$A$5:$A$9,0)) | D6: =COUNTIFS(Datos!$B$5:$B$94,$A6,Datos!$C$5:$C$94,$B6,Datos!$E$5:$E$94,1) | E6: =AVERAGEIFS(Datos!$K$5:$K$94,Datos!$B$5:$B$94,$A6,Datos!$C$5:$C$94,$B6,Datos!$E$5:$E$94,1) | F6: =IF(D6>1,SQRT(MAX(0,(SUMIFS(Datos!$L$5:$L$94,Datos!$B$5:$B$94,$A6,Datos!$C$5:$C$94,$B6,Datos!$E$5:$E$94,1)-D6*E6^2)/(D6-1))),0) | G6: =IF(D6<3,"duplicado","") | I6: KRT2 | J6: =SUMIFS($E$4:$E$28,$A$4:$A$28,J4,$B$4:$B$28,$I6) | K6: =SUMIFS($E$4:$E$28,$A$4:$A$28,K4,$B$4:$B$28,$I6) | L6: =SUMIFS($E$4:$E$28,$A$4:$A$28,L4,$B$4:$B$28,$I6)
A7: KerCT 0 días MD2 | B7: KRT14 | C7: =INDEX(Controles!$B$5:$B$9,MATCH(A7,Controles!$A$5:$A$9,0)) | D7: =COUNTIFS(Datos!$B$5:$B$94,$A7,Datos!$C$5:$C$94,$B7,Datos!$E$5:$E$94,1) | E7: =AVERAGEIFS(Datos!$K$5:$K$94,Datos!$B$5:$B$94,$A7,Datos!$C$5:$C$94,$B7,Datos!$E$5:$E$94,1) | F7: =IF(D7>1,SQRT(MAX(0,(SUMIFS(Datos!$L$5:$L$94,Datos!$B$5:$B$94,$A7,Datos!$C$5:$C$94,$B7,Datos!$E$5:$E$94,1)-D7*E7^2)/(D7-1))),0) | G7: =IF(D7<3,"duplicado","") | I7: KRT10 | J7: =SUMIFS($E$4:$E$28,$A$4:$A$28,J4,$B$4:$B$28,$I7) | K7: =SUMIFS($E$4:$E$28,$A$4:$A$28,K4,$B$4:$B$28,$I7) | L7: =SUMIFS($E$4:$E$28,$A$4:$A$28,L4,$B$4:$B$28,$I7)
A8: KerCT 0 días MD2 | B8: IVL | C8: =INDEX(Controles!$B$5:$B$9,MATCH(A8,Controles!$A$5:$A$9,0)) | D8: =COUNTIFS(Datos!$B$5:$B$94,$A8,Datos!$C$5:$C$94,$B8,Datos!$E$5:$E$94,1) | E8: =AVERAGEIFS(Datos!$K$5:$K$94,Datos!$B$5:$B$94,$A8,Datos!$C$5:$C$94,$B8,Datos!$E$5:$E$94,1) | F8: =IF(D8>1,SQRT(MAX(0,(SUMIFS(Datos!$L$5:$L$94,Datos!$B$5:$B$94,$A8,Datos!$C$5:$C$94,$B8,Datos!$E$5:$E$94,1)-D8*E8^2)/(D8-1))),0) | G8: =IF(D8<3,"duplicado","") | I8: KRT14 | J8: =SUMIFS($E$4:$E$28,$A$4:$A$28,J4,$B$4:$B$28,$I8) | K8: =SUMIFS($E$4:$E$28,$A$4:$A$28,K4,$B$4:$B$28,$I8) | L8: =SUMIFS($E$4:$E$28,$A$4:$A$28,L4,$B$4:$B$28,$I8)
A9: KerCT 7 días MD2 1 | B9: KRT1 | C9: =INDEX(Controles!$B$5:$B$9,MATCH(A9,Controles!$A$5:$A$9,0)) | D9: =COUNTIFS(Datos!$B$5:$B$94,$A9,Datos!$C$5:$C$94,$B9,Datos!$E$5:$E$94,1) | E9: =AVERAGEIFS(Datos!$K$5:$K$94,Datos!$B$5:$B$94,$A9,Datos!$C$5:$C$94,$B9,Datos!$E$5:$E$94,1) | F9: =IF(D9>1,SQRT(MAX(0,(SUMIFS(Datos!$L$5:$L$94,Datos!$B$5:$B$94,$A9,Datos!$C$5:$C$94,$B9,Datos!$E$5:$E$94,1)-D9*E9^2)/(D9-1))),0) | G9: =IF(D9<3,"duplicado","") | I9: IVL | J9: =SUMIFS($E$4:$E$28,$A$4:$A$28,J4,$B$4:$B$28,$I9) | K9: =SUMIFS($E$4:$E$28,$A$4:$A$28,K4,$B$4:$B$28,$I9) | L9: =SUMIFS($E$4:$E$28,$A$4:$A$28,L4,$B$4:$B$28,$I9)
A10: KerCT 7 días MD2 1 | B10: KRT2 | C10: =INDEX(Controles!$B$5:$B$9,MATCH(A10,Controles!$A$5:$A$9,0)) | D10: =COUNTIFS(Datos!$B$5:$B$94,$A10,Datos!$C$5:$C$94,$B10,Datos!$E$5:$E$94,1) | E10: =AVERAGEIFS(Datos!$K$5:$K$94,Datos!$B$5:$B$94,$A10,Datos!$C$5:$C$94,$B10,Datos!$E$5:$E$94,1) | F10: =IF(D10>1,SQRT(MAX(0,(SUMIFS(Datos!$L$5:$L$94,Datos!$B$5:$B$94,$A10,Datos!$C$5:$C$94,$B10,Datos!$E$5:$E$94,1)-D10*E10^2)/(D10-1))),0) | G10: =IF(D10<3,"duplicado","")
A11: KerCT 7 días MD2 1 | B11: KRT10 | C11: =INDEX(Controles!$B$5:$B$9,MATCH(A11,Controles!$A$5:$A$9,0)) | D11: =COUNTIFS(Datos!$B$5:$B$94,$A11,Datos!$C$5:$C$94,$B11,Datos!$E$5:$E$94,1) | E11: =AVERAGEIFS(Datos!$K$5:$K$94,Datos!$B$5:$B$94,$A11,Datos!$C$5:$C$94,$B11,Datos!$E$5:$E$94,1) | F11: =IF(D11>1,SQRT(MAX(0,(SUMIFS(Datos!$L$5:$L$94,Datos!$B$5:$B$94,$A11,Datos!$C$5:$C$94,$B11,Datos!$E$5:$E$94,1)-D11*E11^2)/(D11-1))),0) | G11: =IF(D11<3,"duplicado","") | I11: MD2 – SD
A12: KerCT 7 días MD2 1 | B12: KRT14 | C12: =INDEX(Controles!$B$5:$B$9,MATCH(A12,Controles!$A$5:$A$9,0)) | D12: =COUNTIFS(Datos!$B$5:$B$94,$A12,Datos!$C$5:$C$94,$B12,Datos!$E$5:$E$94,1) | E12: =AVERAGEIFS(Datos!$K$5:$K$94,Datos!$B$5:$B$94,$A12,Datos!$C$5:$C$94,$B12,Datos!$E$5:$E$94,1) | F12: =IF(D12>1,SQRT(MAX(0,(SUMIFS(Datos!$L$5:$L$94,Datos!$B$5:$B$94,$A12,Datos!$C$5:$C$94,$B12,Datos!$E$5:$E$94,1)-D12*E12^2)/(D12-1))),0) | G12: =IF(D12<3,"duplicado","") | I12: Gen | J12: KerCT 0 días MD2 | K12: KerCT 7 días MD2 1 | L12: KerCT 7 días MD2 2
A13: KerCT 7 días MD2 1 | B13: IVL | C13: =INDEX(Controles!$B$5:$B$9,MATCH(A13,Controles!$A$5:$A$9,0)) | D13: =COUNTIFS(Datos!$B$5:$B$94,$A13,Datos!$C$5:$C$94,$B13,Datos!$E$5:$E$94,1) | E13: =AVERAGEIFS(Datos!$K$5:$K$94,Datos!$B$5:$B$94,$A13,Datos!$C$5:$C$94,$B13,Datos!$E$5:$E$94,1) | F13: =IF(D13>1,SQRT(MAX(0,(SUMIFS(Datos!$L$5:$L$94,Datos!$B$5:$B$94,$A13,Datos!$C$5:$C$94,$B13,Datos!$E$5:$E$94,1)-D13*E13^2)/(D13-1))),0) | G13: =IF(D13<3,"duplicado","") | I13: KRT1 | J13: =SUMIFS($F$4:$F$28,$A$4:$A$28,J12,$B$4:$B$28,$I13) | K13: =SUMIFS($F$4:$F$28,$A$4:$A$28,K12,$B$4:$B$28,$I13) | L13: =SUMIFS($F$4:$F$28,$A$4:$A$28,L12,$B$4:$B$28,$I13)
A14: KerCT 7 días MD2 2 | B14: KRT1 | C14: =INDEX(Controles!$B$5:$B$9,MATCH(A14,Controles!$A$5:$A$9,0)) | D14: =COUNTIFS(Datos!$B$5:$B$94,$A14,Datos!$C$5:$C$94,$B14,Datos!$E$5:$E$94,1) | E14: =AVERAGEIFS(Datos!$K$5:$K$94,Datos!$B$5:$B$94,$A14,Datos!$C$5:$C$94,$B14,Datos!$E$5:$E$94,1) | F14: =IF(D14>1,SQRT(MAX(0,(SUMIFS(Datos!$L$5:$L$94,Datos!$B$5:$B$94,$A14,Datos!$C$5:$C$94,$B14,Datos!$E$5:$E$94,1)-D14*E14^2)/(D14-1))),0) | G14: =IF(D14<3,"duplicado","") | I14: KRT2 | J14: =SUMIFS($F$4:$F$28,$A$4:$A$28,J12,$B$4:$B$28,$I14) | K14: =SUMIFS($F$4:$F$28,$A$4:$A$28,K12,$B$4:$B$28,$I14) | L14: =SUMIFS($F$4:$F$28,$A$4:$A$28,L12,$B$4:$B$28,$I14)
A15: KerCT 7 días MD2 2 | B15: KRT2 | C15: =INDEX(Controles!$B$5:$B$9,MATCH(A15,Controles!$A$5:$A$9,0)) | D15: =COUNTIFS(Datos!$B$5:$B$94,$A15,Datos!$C$5:$C$94,$B15,Datos!$E$5:$E$94,1) | E15: =AVERAGEIFS(Datos!$K$5:$K$94,Datos!$B$5:$B$94,$A15,Datos!$C$5:$C$94,$B15,Datos!$E$5:$E$94,1) | F15: =IF(D15>1,SQRT(MAX(0,(SUMIFS(Datos!$L$5:$L$94,Datos!$B$5:$B$94,$A15,Datos!$C$5:$C$94,$B15,Datos!$E$5:$E$94,1)-D15*E15^2)/(D15-1))),0) | G15: =IF(D15<3,"duplicado","") | I15: KRT10 | J15: =SUMIFS($F$4:$F$28,$A$4:$A$28,J12,$B$4:$B$28,$I15) | K15: =SUMIFS($F$4:$F$28,$A$4:$A$28,K12,$B$4:$B$28,$I15) | L15: =SUMIFS($F$4:$F$28,$A$4:$A$28,L12,$B$4:$B$28,$I15)
A16: KerCT 7 días MD2 2 | B16: KRT10 | C16: =INDEX(Controles!$B$5:$B$9,MATCH(A16,Controles!$A$5:$A$9,0)) | D16: =COUNTIFS(Datos!$B$5:$B$94,$A16,Datos!$C$5:$C$94,$B16,Datos!$E$5:$E$94,1) | E16: =AVERAGEIFS(Datos!$K$5:$K$94,Datos!$B$5:$B$94,$A16,Datos!$C$5:$C$94,$B16,Datos!$E$5:$E$94,1) | F16: =IF(D16>1,SQRT(MAX(0,(SUMIFS(Datos!$L$5:$L$94,Datos!$B$5:$B$94,$A16,Datos!$C$5:$C$94,$B16,Datos!$E$5:$E$94,1)-D16*E16^2)/(D16-1))),0) | G16: =IF(D16<3,"duplicado","") | I16: KRT14 | J16: =SUMIFS($F$4:$F$28,$A$4:$A$28,J12,$B$4:$B$28,$I16) | K16: =SUMIFS($F$4:$F$28,$A$4:$A$28,K12,$B$4:$B$28,$I16) | L16: =SUMIFS($F$4:$F$28,$A$4:$A$28,L12,$B$4:$B$28,$I16)
A17: KerCT 7 días MD2 2 | B17: KRT14 | C17: =INDEX(Controles!$B$5:$B$9,MATCH(A17,Controles!$A$5:$A$9,0)) | D17: =COUNTIFS(Datos!$B$5:$B$94,$A17,Datos!$C$5:$C$94,$B17,Datos!$E$5:$E$94,1) | E17: =AVERAGEIFS(Datos!$K$5:$K$94,Datos!$B$5:$B$94,$A17,Datos!$C$5:$C$94,$B17,Datos!$E$5:$E$94,1) | F17: =IF(D17>1,SQRT(MAX(0,(SUMIFS(Datos!$L$5:$L$94,Datos!$B$5:$B$94,$A17,Datos!$C$5:$C$94,$B17,Datos!$E$5:$E$94,1)-D17*E17^2)/(D17-1))),0) | G17: =IF(D17<3,"duplicado","") | I17: IVL | J17: =SUMIFS($F$4:$F$28,$A$4:$A$28,J12,$B$4:$B$28,$I17) | K17: =SUMIFS($F$4:$F$28,$A$4:$A$28,K12,$B$4:$B$28,$I17) | L17: =SUMIFS($F$4:$F$28,$A$4:$A$28,L12,$B$4:$B$28,$I17)
A18: KerCT 7 días MD2 2 | B18: IVL | C18: =INDEX(Controles!$B$5:$B$9,MATCH(A18,Controles!$A$5:$A$9,0)) | D18: =COUNTIFS(Datos!$B$5:$B$94,$A18,Datos!$C$5:$C$94,$B18,Datos!$E$5:$E$94,1) | E18: =AVERAGEIFS(Datos!$K$5:$K$94,Datos!$B$5:$B$94,$A18,Datos!$C$5:$C$94,$B18,Datos!$E$5:$E$94,1) | F18: =IF(D18>1,SQRT(MAX(0,(SUMIFS(Datos!$L$5:$L$94,Datos!$B$5:$B$94,$A18,Datos!$C$5:$C$94,$B18,Datos!$E$5:$E$94,1)-D18*E18^2)/(D18-1))),0) | G18: =IF(D18<3,"duplicado","")
A19: KerCT 0 días MD3 | B19: KRT1 | C19: =INDEX(Controles!$B$5:$B$9,MATCH(A19,Controles!$A$5:$A$9,0)) | D19: =COUNTIFS(Datos!$B$5:$B$94,$A19,Datos!$C$5:$C$94,$B19,Datos!$E$5:$E$94,1) | E19: =AVERAGEIFS(Datos!$K$5:$K$94,Datos!$B$5:$B$94,$A19,Datos!$C$5:$C$94,$B19,Datos!$E$5:$E$94,1) | F19: =IF(D19>1,SQRT(MAX(0,(SUMIFS(Datos!$L$5:$L$94,Datos!$B$5:$B$94,$A19,Datos!$C$5:$C$94,$B19,Datos!$E$5:$E$94,1)-D19*E19^2)/(D19-1))),0) | G19: =IF(D19<3,"duplicado","")
A20: KerCT 0 días MD3 | B20: KRT2 | C20: =INDEX(Controles!$B$5:$B$9,MATCH(A20,Controles!$A$5:$A$9,0)) | D20: =COUNTIFS(Datos!$B$5:$B$94,$A20,Datos!$C$5:$C$94,$B20,Datos!$E$5:$E$94,1) | E20: =AVERAGEIFS(Datos!$K$5:$K$94,Datos!$B$5:$B$94,$A20,Datos!$C$5:$C$94,$B20,Datos!$E$5:$E$94,1) | F20: =IF(D20>1,SQRT(MAX(0,(SUMIFS(Datos!$L$5:$L$94,Datos!$B$5:$B$94,$A20,Datos!$C$5:$C$94,$B20,Datos!$E$5:$E$94,1)-D20*E20^2)/(D20-1))),0) | G20: =IF(D20<3,"duplicado","") | I20: MD3 – RQ media
A21: KerCT 0 días MD3 | B21: KRT10 | C21: =INDEX(Controles!$B$5:$B$9,MATCH(A21,Controles!$A$5:$A$9,0)) | D21: =COUNTIFS(Datos!$B$5:$B$94,$A21,Datos!$C$5:$C$94,$B21,Datos!$E$5:$E$94,1) | E21: =AVERAGEIFS(Datos!$K$5:$K$94,Datos!$B$5:$B$94,$A21,Datos!$C$5:$C$94,$B21,Datos!$E$5:$E$94,1) | F21: =IF(D21>1,SQRT(MAX(0,(SUMIFS(Datos!$L$5:$L$94,Datos!$B$5:$B$94,$A21,Datos!$C$5:$C$94,$B21,Datos!$E$5:$E$94,1)-D21*E21^2)/(D21-1))),0) | G21: =IF(D21<3,"duplicado","") | I21: Gen | J21: KerCT 0 días MD3 | K21: KerCT 7 días MD3
A22: KerCT 0 días MD3 | B22: KRT14 | C22: =INDEX(Controles!$B$5:$B$9,MATCH(A22,Controles!$A$5:$A$9,0)) | D22: =COUNTIFS(Datos!$B$5:$B$94,$A22,Datos!$C$5:$C$94,$B22,Datos!$E$5:$E$94,1) | E22: =AVERAGEIFS(Datos!$K$5:$K$94,Datos!$B$5:$B$94,$A22,Datos!$C$5:$C$94,$B22,Datos!$E$5:$E$94,1) | F22: =IF(D22>1,SQRT(MAX(0,(SUMIFS(Datos!$L$5:$L$94,Datos!$B$5:$B$94,$A22,Datos!$C$5:$C$94,$B22,Datos!$E$5:$E$94,1)-D22*E22^2)/(D22-1))),0) | G22: =IF(D22<3,"duplicado","") | I22: KRT1 | J22: =SUMIFS($E$4:$E$28,$A$4:$A$28,J21,$B$4:$B$28,$I22) | K22: =SUMIFS($E$4:$E$28,$A$4:$A$28,K21,$B$4:$B$28,$I22)
A23: KerCT 0 días MD3 | B23: IVL | C23: =INDEX(Controles!$B$5:$B$9,MATCH(A23,Controles!$A$5:$A$9,0)) | D23: =COUNTIFS(Datos!$B$5:$B$94,$A23,Datos!$C$5:$C$94,$B23,Datos!$E$5:$E$94,1) | E23: =AVERAGEIFS(Datos!$K$5:$K$94,Datos!$B$5:$B$94,$A23,Datos!$C$5:$C$94,$B23,Datos!$E$5:$E$94,1) | F23: =IF(D23>1,SQRT(MAX(0,(SUMIFS(Datos!$L$5:$L$94,Datos!$B$5:$B$94,$A23,Datos!$C$5:$C$94,$B23,Datos!$E$5:$E$94,1)-D23*E23^2)/(D23-1))),0) | G23: =IF(D23<3,"duplicado","") | I23: KRT2 | J23: =SUMIFS($E$4:$E$28,$A$4:$A$28,J21,$B$4:$B$28,$I23) | K23: =SUMIFS($E$4:$E$28,$A$4:$A$28,K21,$B$4:$B$28,$I23)
A24: KerCT 7 días MD3 | B24: KRT1 | C24: =INDEX(Controles!$B$5:$B$9,MATCH(A24,Controles!$A$5:$A$9,0)) | D24: =COUNTIFS(Datos!$B$5:$B$94,$A24,Datos!$C$5:$C$94,$B24,Datos!$E$5:$E$94,1) | E24: =AVERAGEIFS(Datos!$K$5:$K$94,Datos!$B$5:$B$94,$A24,Datos!$C$5:$C$94,$B24,Datos!$E$5:$E$94,1) | F24: =IF(D24>1,SQRT(MAX(0,(SUMIFS(Datos!$L$5:$L$94,Datos!$B$5:$B$94,$A24,Datos!$C$5:$C$94,$B24,Datos!$E$5:$E$94,1)-D24*E24^2)/(D24-1))),0) | G24: =IF(D24<3,"duplicado","") | I24: KRT10 | J24: =SUMIFS($E$4:$E$28,$A$4:$A$28,J21,$B$4:$B$28,$I24) | K24: =SUMIFS($E$4:$E$28,$A$4:$A$28,K21,$B$4:$B$28,$I24)
A25: KerCT 7 días MD3 | B25: KRT2 | C25: =INDEX(Controles!$B$5:$B$9,MATCH(A25,Controles!$A$5:$A$9,0)) | D25: =COUNTIFS(Datos!$B$5:$B$94,$A25,Datos!$C$5:$C$94,$B25,Datos!$E$5:$E$94,1) | E25: =AVERAGEIFS(Datos!$K$5:$K$94,Datos!$B$5:$B$94,$A25,Datos!$C$5:$C$94,$B25,Datos!$E$5:$E$94,1) | F25: =IF(D25>1,SQRT(MAX(0,(SUMIFS(Datos!$L$5:$L$94,Datos!$B$5:$B$94,$A25,Datos!$C$5:$C$94,$B25,Datos!$E$5:$E$94,1)-D25*E25^2)/(D25-1))),0) | G25: =IF(D25<3,"duplicado","") | I25: KRT14 | J25: =SUMIFS($E$4:$E$28,$A$4:$A$28,J21,$B$4:$B$28,$I25) | K25: =SUMIFS($E$4:$E$28,$A$4:$A$28,K21,$B$4:$B$28,$I25)
A26: KerCT 7 días MD3 | B26: KRT10 | C26: =INDEX(Controles!$B$5:$B$9,MATCH(A26,Controles!$A$5:$A$9,0)) | D26: =COUNTIFS(Datos!$B$5:$B$94,$A26,Datos!$C$5:$C$94,$B26,Datos!$E$5:$E$94,1) | E26: =AVERAGEIFS(Datos!$K$5:$K$94,Datos!$B$5:$B$94,$A26,Datos!$C$5:$C$94,$B26,Datos!$E$5:$E$94,1) | F26: =IF(D26>1,SQRT(MAX(0,(SUMIFS(Datos!$L$5:$L$94,Datos!$B$5:$B$94,$A26,Datos!$C$5:$C$94,$B26,Datos!$E$5:$E$94,1)-D26*E26^2)/(D26-1))),0) | G26: =IF(D26<3,"duplicado","") | I26: IVL | J26: =SUMIFS($E$4:$E$28,$A$4:$A$28,J21,$B$4:$B$28,$I26) | K26: =SUMIFS($E$4:$E$28,$A$4:$A$28,K21,$B$4:$B$28,$I26)
A27: KerCT 7 días MD3 | B27: KRT14 | C27: =INDEX(Controles!$B$5:$B$9,MATCH(A27,Controles!$A$5:$A$9,0)) | D27: =COUNTIFS(Datos!$B$5:$B$94,$A27,Datos!$C$5:$C$94,$B27,Datos!$E$5:$E$94,1) | E27: =AVERAGEIFS(Datos!$K$5:$K$94,Datos!$B$5:$B$94,$A27,Datos!$C$5:$C$94,$B27,Datos!$E$5:$E$94,1) | F27: =IF(D27>1,SQRT(MAX(0,(SUMIFS(Datos!$L$5:$L$94,Datos!$B$5:$B$94,$A27,Datos!$C$5:$C$94,$B27,Datos!$E$5:$E$94,1)-D27*E27^2)/(D27-1))),0) | G27: =IF(D27<3,"duplicado","")
A28: KerCT 7 días MD3 | B28: IVL | C28: =INDEX(Controles!$B$5:$B$9,MATCH(A28,Controles!$A$5:$A$9,0)) | D28: =COUNTIFS(Datos!$B$5:$B$94,$A28,Datos!$C$5:$C$94,$B28,Datos!$E$5:$E$94,1) | E28: =AVERAGEIFS(Datos!$K$5:$K$94,Datos!$B$5:$B$94,$A28,Datos!$C$5:$C$94,$B28,Datos!$E$5:$E$94,1) | F28: =IF(D28>1,SQRT(MAX(0,(SUMIFS(Datos!$L$5:$L$94,Datos!$B$5:$B$94,$A28,Datos!$C$5:$C$94,$B28,Datos!$E$5:$E$94,1)-D28*E28^2)/(D28-1))),0) | G28: =IF(D28<3,"duplicado","") | I28: MD3 – SD
I29: Gen | J29: KerCT 0 días MD3 | K29: KerCT 7 días MD3
I30: KRT1 | J30: =SUMIFS($F$4:$F$28,$A$4:$A$28,J29,$B$4:$B$28,$I30) | K30: =SUMIFS($F$4:$F$28,$A$4:$A$28,K29,$B$4:$B$28,$I30)
I31: KRT2 | J31: =SUMIFS($F$4:$F$28,$A$4:$A$28,J29,$B$4:$B$28,$I31) | K31: =SUMIFS($F$4:$F$28,$A$4:$A$28,K29,$B$4:$B$28,$I31)
I32: KRT10 | J32: =SUMIFS($F$4:$F$28,$A$4:$A$28,J29,$B$4:$B$28,$I32) | K32: =SUMIFS($F$4:$F$28,$A$4:$A$28,K29,$B$4:$B$28,$I32)
I33: KRT14 | J33: =SUMIFS($F$4:$F$28,$A$4:$A$28,J29,$B$4:$B$28,$I33) | K33: =SUMIFS($F$4:$F$28,$A$4:$A$28,K29,$B$4:$B$28,$I33)
I34: IVL | J34: =SUMIFS($F$4:$F$28,$A$4:$A$28,J29,$B$4:$B$28,$I34) | K34: =SUMIFS($F$4:$F$28,$A$4:$A$28,K29,$B$4:$B$28,$I34)
I37: MD2 7d – réplicas biológicas (MD2 1 y MD2 2): media y SD entre las dos
I38: Gen | J38: Control 0d MD2 | K38: 7d MD2 (media MD2 1 y 2) | L38: SD control | M38: SD entre réplicas (n=2)
I39: KRT1 | J39: =J5 | K39: =AVERAGE(K5,L5) | L39: 0 | M39: =STDEV(K5,L5)
I40: KRT2 | J40: =J6 | K40: =AVERAGE(K6,L6) | L40: 0 | M40: =STDEV(K6,L6)
I41: KRT10 | J41: =J7 | K41: =AVERAGE(K7,L7) | L41: 0 | M41: =STDEV(K7,L7)
I42: KRT14 | J42: =J8 | K42: =AVERAGE(K8,L8) | L42: 0 | M42: =STDEV(K8,L8)
I43: IVL | J43: =J9 | K43: =AVERAGE(K9,L9) | L43: 0 | M43: =STDEV(K9,L9)
...

Sheet Gráficas
A1: RQ media ± SD (eje logarítmico). La línea de RQ=1 es la muestra control.

Sheet Medio3D
A1: Medio 3D (Prism, 2026-07-16): RQ relativo al día 0 de ese medio
A2: Datos copiados del .prism (hojas "rep 1" y "rep2", azul = dato). Cada gen tiene 2 columnas por hoja. Supuesto: rep1 y rep2 son réplicas biológicas; dentro de cada una combino sus 2 columnas con media geométrica. Ojo: columna 1 es idéntica en rep1 y rep2, y las dos columnas difieren hasta 370 veces.
A4: Gen | B4: Día | C4: rep1 col 1 | D4: rep1 col 2 | E4: rep2 col 1 | F4: rep2 col 2 | G4: rep1 (media geom.) | H4: rep2 (media geom.) | I4: Media rep1-2 | J4: SD entre rep1-2
A5: KRT1 | B5: 0 | C5: 1 | D5: 1 | E5: 1 | F5: 1 | G5: =GEOMEAN(C5,D5) | H5: =GEOMEAN(E5,F5) | I5: =AVERAGE(G5,H5) | J5: =STDEV(G5,H5)
A6: KRT1 | B6: 7 | C6: 518.45638 | D6: 1.3800268 | E6: 518.45638 | F6: 63.385522 | G6: =GEOMEAN(C6,D6) | H6: =GEOMEAN(E6,F6) | I6: =AVERAGE(G6,H6) | J6: =STDEV(G6,H6)
A7: KRT1 | B7: 14 | C7: 183.21612 | D7: 1639.9192 | E7: 183.21612 | F7: 10186.233 | G7: =GEOMEAN(C7,D7) | H7: =GEOMEAN(E7,F7) | I7: =AVERAGE(G7,H7) | J7: =STDEV(G7,H7)
A8: KRT1 | B8: 20 | C8: 1.2045696 | D8: 74.998094 | E8: 1.2045696 | F8: 506.7799 | G8: =GEOMEAN(C8,D8) | H8: =GEOMEAN(E8,F8) | I8: =AVERAGE(G8,H8) | J8: =STDEV(G8,H8)
A9: KRT10 | B9: 0 | C9: 1 | D9: 1 | E9: 1 | F9: 1 | G9: =GEOMEAN(C9,D9) | H9: =GEOMEAN(E9,F9) | I9: =AVERAGE(G9,H9) | J9: =STDEV(G9,H9)
A10: KRT10 | B10: 7 | C10: 1434.0673 | D10: 3.5625099 | E10: 1434.0673 | F10: 214.89272 | G10: =GEOMEAN(C10,D10) | H10: =GEOMEAN(E10,F10) | I10: =AVERAGE(G10,H10) | J10: =STDEV(G10,H10)
A11: KRT10 | B11: 14 | C11: 2341.2801 | D11: 273.19071 | E11: 2341.2801 | F11: 1972.3367 | G11: =GEOMEAN(C11,D11) | H11: =GEOMEAN(E11,F11) | I11: =AVERAGE(G11,H11) | J11: =STDEV(G11,H11)
A12: KRT10 | B12: 20 | C12: 5.6935941 | D12: 18.282358 | E12: 5.6935941 | F12: 118.22598 | G12: =GEOMEAN(C12,D12) | H12: =GEOMEAN(E12,F12) | I12: =AVERAGE(G12,H12) | J12: =STDEV(G12,H12)
A13: KRT2 | B13: 0 | C13: 1 | D13: 1 | E13: 1 | F13: 1 | G13: =GEOMEAN(C13,D13) | H13: =GEOMEAN(E13,F13) | I13: =AVERAGE(G13,H13) | J13: =STDEV(G13,H13)
A14: KRT2 | B14: 7 | C14: 2.0492466 | D14: 4.9884472 | E14: 2.0492466 | F14: 4.9884472 | G14: =GEOMEAN(C14,D14) | H14: =GEOMEAN(E14,F14) | I14: =AVERAGE(G14,H14) | J14: =STDEV(G14,H14)
A15: KRT2 | B15: 14 | C15: 4.2133405 | D15: 377.29587 | E15: 4.2133405 | F15: 377.29587 | G15: =GEOMEAN(C15,D15) | H15: =GEOMEAN(E15,F15) | I15: =AVERAGE(G15,H15) | J15: =STDEV(G15,H15)
A16: KRT2 | B16: 20 | C16: 0.25236829 | D16: 49.615327 | E16: 0.25236829 | F16: 49.615327 | G16: =GEOMEAN(C16,D16) | H16: =GEOMEAN(E16,F16) | I16: =AVERAGE(G16,H16) | J16: =STDEV(G16,H16)
... A28: KRT14 | B28: 20 | C28: 1.26152 | D28: 0.82330068 | E28: 1.26152 | F28: 0.82330068 | G28: =GEOMEAN(C28,D28) | H28: =GEOMEAN(E28,F28) | I28: =AVERAGE(G28,H28) | J28: =STDEV(G28,H28)

Sheet Comparación
A1: MD2 (7 días, media de MD2 1 y 2) vs Medio 3D (media de rep1 y rep2)
A2: Cada medio va relativo a su propio día 0. SD = entre las 2 réplicas biológicas (n=2). KRT5 no se midió en MD2.
A4: Gen | B4: MD2 7d | C4: Medio 3D 7d | D4: SD MD2 | E4: SD Medio 3D | F4: Medio 3D / MD2
A5: KRT1 | B5: =Resumen!K39 | C5: =SUMIFS(Medio3D!$I$5:$I$28,Medio3D!$A$5:$A$28,$A5,Medio3D!$B$5:$B$28,7) | D5: =Resumen!M39 | E5: =SUMIFS(Medio3D!$J$5:$J$28,Medio3D!$A$5:$A$28,$A5,Medio3D!$B$5:$B$28,7) | F5: =IF(B5=0,"",C5/B5)
A6: KRT2 | B6: =Resumen!K40 | C6: =SUMIFS(Medio3D!$I$5:$I$28,Medio3D!$A$5:$A$28,$A6,Medio3D!$B$5:$B$28,7) | D6: =Resumen!M40 | E6: =SUMIFS(Medio3D!$J$5:$J$28,Medio3D!$A$5:$A$28,$A6,Medio3D!$B$5:$B$28,7) | F6: =IF(B6=0,"",C6/B6)
A7: KRT10 | B7: =Resumen!K41 | C7: =SUMIFS(Medio3D!$I$5:$I$28,Medio3D!$A$5:$A$28,$A7,Medio3D!$B$5:$B$28,7) | D7: =Resumen!M41 | E7: =SUMIFS(Medio3D!$J$5:$J$28,Medio3D!$A$5:$A$28,$A7,Medio3D!$B$5:$B$28,7) | F7: =IF(B7=0,"",C7/B7)
A8: KRT14 | B8: =Resumen!K42 | C8: =SUMIFS(Medio3D!$I$5:$I$28,Medio3D!$A$5:$A$28,$A8,Medio3D!$B$5:$B$28,7) | D8: =Resumen!M42 | E8: =SUMIFS(Medio3D!$J$5:$J$28,Medio3D!$A$5:$A$28,$A8,Medio3D!$B$5:$B$28,7) | F8: =IF(B8=0,"",C8/B8)
A9: IVL | B9: =Resumen!K43 | C9: =SUMIFS(Medio3D!$I$5:$I$28,Medio3D!$A$5:$A$28,$A9,Medio3D!$B$5:$B$28,7) | D9: =Resumen!M43 | E9: =SUMIFS(Medio3D!$J$5:$J$28,Medio3D!$A$5:$A$28,$A9,Medio3D!$B$5:$B$28,7) | F9: =IF(B9=0,"",C9/B9)
A11: Evolución en el Medio 3D (media de rep1 y rep2)
A12: Gen | B12: 7 d | C12: 14 d | D12: 20 d | E12: SD 7 d | F12: SD 14 d | G12: SD 20 d
A13: KRT1 | B13: =SUMIFS(Medio3D!$I$5:$I$28,Medio3D!$A$5:$A$28,$A13,Medio3D!$B$5:$B$28,7) | C13: =SUMIFS(Medio3D!$I$5:$I$28,Medio3D!$A$5:$A$28,$A13,Medio3D!$B$5:$B$28,14) | D13: =SUMIFS(Medio3D!$I$5:$I$28,Medio3D!$A$5:$A$28,$A13,Medio3D!$B$5:$B$28,20) | E13: =SUMIFS(Medio3D!$J$5:$J$28,Medio3D!$A$5:$A$28,$A13,Medio3D!$B$5:$B$28,7) | F13: =SUMIFS(Medio3D!$J$5:$J$28,Medio3D!$A$5:$A$28,$A13,Medio3D!$B$5:$B$28,14) | G13: =SUMIFS(Medio3D!$J$5:$J$28,Medio3D!$A$5:$A$28,$A13,Medio3D!$B$5:$B$28,20)
A14: KRT10 | B14: =SUMIFS(Medio3D!$I$5:$I$28,Medio3D!$A$5:$A$28,$A14,Medio3D!$B$5:$B$28,7) | C14: =SUMIFS(Medio3D!$I$5:$I$28,Medio3D!$A$5:$A$28,$A14,Medio3D!$B$5:$B$28,14) | D14: =SUMIFS(Medio3D!$I$5:$I$28,Medio3D!$A$5:$A$28,$A14,Medio3D!$B$5:$B$28,20) | E14: =SUMIFS(Medio3D!$J$5:$J$28,Medio3D!$A$5:$A$28,$A14,Medio3D!$B$5:$B$28,7) | F14: =SUMIFS(Medio3D!$J$5:$J$28,Medio3D!$A$5:$A$28,$A14,Medio3D!$B$5:$B$28,14) | G14: =SUMIFS(Medio3D!$J$5:$J$28,Medio3D!$A$5:$A$28,$A14,Medio3D!$B$5:$B$28,20)
A15: KRT2 | B15: =SUMIFS(Medio3D!$I$5:$I$28,Medio3D!$A$5:$A$28,$A15,Medio3D!$B$5:$B$28,7) | C15: =SUMIFS(Medio3D!$I$5:$I$28,Medio3D!$A$5:$A$28,$A15,Medio3D!$B$5:$B$28,14) | D15: =SUMIFS(Medio3D!$I$5:$I$28,Medio3D!$A$5:$A$28,$A15,Medio3D!$B$5:$B$28,20) | E15: =SUMIFS(Medio3D!$J$5:$J$28,Medio3D!$A$5:$A$28,$A15,Medio3D!$B$5:$B$28,7) | F15: =SUMIFS(Medio3D!$J$5:$J$28,Medio3D!$A$5:$A$28,$A15,Medio3D!$B$5:$B$28,14) | G15: =SUMIFS(Medio3D!$J$5:$J$28,Medio3D!$A$5:$A$28,$A15,Medio3D!$B$5:$B$28,20)
A16: IVL | B16: =SUMIFS(Medio3D!$I$5:$I$28,Medio3D!$A$5:$A$28,$A16,Medio3D!$B$5:$B$28,7) | C16: =SUMIFS(Medio3D!$I$5:$I$28,Medio3D!$A$5:$A$28,$A16,Medio3D!$B$5:$B$28,14) | D16: =SUMIFS(Medio3D!$I$5:$I$28,Medio3D!$A$5:$A$28,$A16,Medio3D!$B$5:$B$28,20) | E16: =SUMIFS(Medio3D!$J$5:$J$28,Medio3D!$A$5:$A$28,$A16,Medio3D!$B$5:$B$28,7) | F16: =SUMIFS(Medio3D!$J$5:$J$28,Medio3D!$A$5:$A$28,$A16,Medio3D!$B$5:$B$28,14) | G16: =SUMIFS(Medio3D!$J$5:$J$28,Medio3D!$A$5:$A$28,$A16,Medio3D!$B$5:$B$28,20)
A17: KRT5 | B17: =SUMIFS(Medio3D!$I$5:$I$28,Medio3D!$A$5:$A$28,$A17,Medio3D!$B$5:$B$28,7) | C17: =SUMIFS(Medio3D!$I$5:$I$28,Medio3D!$A$5:$A$28,$A17,Medio3D!$B$5:$B$28,14) | D17: =SUMIFS(Medio3D!$I$5:$I$28,Medio3D!$A$5:$A$28,$A17,Medio3D!$B$5:$B$28,20) | E17: =SUMIFS(Medio3D!$J$5:$J$28,Medio3D!$A$5:$A$28,$A17,Medio3D!$B$5:$B$28,7) | F17: =SUMIFS(Medio3D!$J$5:$J$28,Medio3D!$A$5:$A$28,$A17,Medio3D!$B$5:$B$28,14) | G17: =SUMIFS(Medio3D!$J$5:$J$28,Medio3D!$A$5:$A$28,$A17,Medio3D!$B$5:$B$28,20)
A18: KRT14 | B18: =SUMIFS(Medio3D!$I$5:$I$28,Medio3D!$A$5:$A$28,$A18,Medio3D!$B$5:$B$28,7) | C18: =SUMIFS(Medio3D!$I$5:$I$28,Medio3D!$A$5:$A$28,$A18,Medio3D!$B$5:$B$28,14) | D18: =SUMIFS(Medio3D!$I$5:$I$28,Medio3D!$A$5:$A$28,$A18,Medio3D!$B$5:$B$28,20) | E18: =SUMIFS(Medio3D!$J$5:$J$28,Medio3D!$A$5:$A$28,$A18,Medio3D!$B$5:$B$28,7) | F18: =SUMIFS(Medio3D!$J$5:$J$28,Medio3D!$A$5:$A$28,$A18,Medio3D!$B$5:$B$28,14) | G18: =SUMIFS(Medio3D!$J$5:$J$28,Medio3D!$A$5:$A$28,$A18,Medio3D!$B$5:$B$28,20)
