Workbook

Sheet Analisis
A1: Cuantificación WB queratinocitos diferenciados vs sin diferenciar — normalizado a 14-3-3ζ (canal 700)
A2: Señal = 'Signal' (ya restado el fondo) de Hoja4. Diana = canal 800 (785Ex-820Em); control endógeno 14-3-3ζ = canal 700 (685Ex-720Em).
A3: Límite de detección (señal diana mínima para calcular fold): | G3: 100
A5: Gel | B5: Anticuerpo | C5: Réplica | D5: Condición | E5: ROI diana | F5: Señal diana | G5: ROI 14-3-3ζ | H5: Señal 14-3-3ζ | I5: Diana / 14-3-3ζ
A6: Gel A (K14/K5) | B6: K14 | C6: 1 | D6: Dif | E6: 33 | F6: =IFERROR(Hoja4!$D$34*1,VALUE(SUBSTITUTE(Hoja4!$D$34,",","."))) -> 3420 | G6: 1 | H6: =IFERROR(Hoja4!$D$2*1,VALUE(SUBSTITUTE(Hoja4!$D$2,",","."))) -> 5420 | I6: =IF(ISNUMBER(F6),F6/H6,"n.c.") -> 0.63099631
A7: Gel A (K14/K5) | B7: K14 | C7: 1 | D7: Sin dif | E7: 34 | F7: =IFERROR(Hoja4!$D$35*1,VALUE(SUBSTITUTE(Hoja4!$D$35,",","."))) -> 16100 | G7: 2 | H7: =IFERROR(Hoja4!$D$3*1,VALUE(SUBSTITUTE(Hoja4!$D$3,",","."))) -> 959 | I7: =IF(ISNUMBER(F7),F7/H7,"n.c.") -> 16.788321
A8: Gel A (K14/K5) | B8: K5 | C8: 1 | D8: Dif | E8: 35 | F8: =IFERROR(Hoja4!$D$36*1,VALUE(SUBSTITUTE(Hoja4!$D$36,",","."))) -> 384 | G8: 3 | H8: =IFERROR(Hoja4!$D$4*1,VALUE(SUBSTITUTE(Hoja4!$D$4,",","."))) -> 6620 | I8: =IF(ISNUMBER(F8),F8/H8,"n.c.") -> 0.058006042
A9: Gel A (K14/K5) | B9: K5 | C9: 1 | D9: Sin dif | E9: 36 | F9: =IFERROR(Hoja4!$D$37*1,VALUE(SUBSTITUTE(Hoja4!$D$37,",","."))) -> 4490 | G9: 4 | H9: =IFERROR(Hoja4!$D$5*1,VALUE(SUBSTITUTE(Hoja4!$D$5,",","."))) -> 1430 | I9: =IF(ISNUMBER(F9),F9/H9,"n.c.") -> 3.1398601
A10: Gel A (K14/K5) | B10: K5 | C10: 2 | D10: Dif | E10: 37 | F10: =IFERROR(Hoja4!$D$38*1,VALUE(SUBSTITUTE(Hoja4!$D$38,",","."))) -> 348 | G10: 5 | H10: =IFERROR(Hoja4!$D$6*1,VALUE(SUBSTITUTE(Hoja4!$D$6,",","."))) -> 9070 | I10: =IF(ISNUMBER(F10),F10/H10,"n.c.") -> 0.038368247
A11: Gel A (K14/K5) | B11: K5 | C11: 2 | D11: Sin dif | E11: 38 | F11: =IFERROR(Hoja4!$D$39*1,VALUE(SUBSTITUTE(Hoja4!$D$39,",","."))) -> 3260 | G11: 6 | H11: =IFERROR(Hoja4!$D$7*1,VALUE(SUBSTITUTE(Hoja4!$D$7,",","."))) -> 2070 | I11: =IF(ISNUMBER(F11),F11/H11,"n.c.") -> 1.5748792
A12: Gel B (K1/K10 ab) | B12: K1 | C12: 1 | D12: Dif | E12: 39 | F12: =IFERROR(Hoja4!$D$40*1,VALUE(SUBSTITUTE(Hoja4!$D$40,",","."))) -> 273 | G12: 7 | H12: =IFERROR(Hoja4!$D$8*1,VALUE(SUBSTITUTE(Hoja4!$D$8,",","."))) -> 11100 | I12: =IF(ISNUMBER(F12),F12/H12,"n.c.") -> 0.024594595
A13: Gel B (K1/K10 ab) | B13: K1 | C13: 1 | D13: Sin dif | E13: 40 | F13: =IFERROR(Hoja4!$D$41*1,VALUE(SUBSTITUTE(Hoja4!$D$41,",","."))) -> 1490 | G13: 8 | H13: =IFERROR(Hoja4!$D$9*1,VALUE(SUBSTITUTE(Hoja4!$D$9,",","."))) -> 1150 | I13: =IF(ISNUMBER(F13),F13/H13,"n.c.") -> 1.2956522
A14: Gel B (K1/K10 ab) | B14: K1 | C14: 2 | D14: Dif | E14: 41 | F14: =IFERROR(Hoja4!$D$42*1,VALUE(SUBSTITUTE(Hoja4!$D$42,",","."))) -> 138 | G14: 9 | H14: =IFERROR(Hoja4!$D$10*1,VALUE(SUBSTITUTE(Hoja4!$D$10,",","."))) -> 7460 | I14: =IF(ISNUMBER(F14),F14/H14,"n.c.") -> 0.01849866
A15: Gel B (K1/K10 ab) | B15: K1 | C15: 2 | D15: Sin dif | E15: 42 | F15: =IFERROR(Hoja4!$D$43*1,VALUE(SUBSTITUTE(Hoja4!$D$43,",","."))) -> 1200 | G15: 10 | H15: =IFERROR(Hoja4!$D$11*1,VALUE(SUBSTITUTE(Hoja4!$D$11,",","."))) -> 1610 | I15: =IF(ISNUMBER(F15),F15/H15,"n.c.") -> 0.74534161
A16: Gel B (K1/K10 ab) | B16: K10 ab | C16: 1 | D16: Dif | E16: 43 | F16: =IFERROR(Hoja4!$D$44*1,VALUE(SUBSTITUTE(Hoja4!$D$44,",","."))) -> 3300 | G16: 11 | H16: =IFERROR(Hoja4!$D$12*1,VALUE(SUBSTITUTE(Hoja4!$D$12,",","."))) -> 7910 | I16: =IF(ISNUMBER(F16),F16/H16,"n.c.") -> 0.41719343
A17: Gel B (K1/K10 ab) | B17: K10 ab | C17: 1 | D17: Sin dif | E17: 45 | F17: =IFERROR(Hoja4!$D$46*1,VALUE(SUBSTITUTE(Hoja4!$D$46,",","."))) -> 3.6 | G17: 12 | H17: =IFERROR(Hoja4!$D$13*1,VALUE(SUBSTITUTE(Hoja4!$D$13,",","."))) -> 2050 | I17: =IF(ISNUMBER(F17),F17/H17,"n.c.") -> 0.0017560976
A18: Gel C (K2/K10 int) | B18: K2 | C18: 1 | D18: Dif | E18: 25 | F18: =IFERROR(Hoja4!$D$26*1,VALUE(SUBSTITUTE(Hoja4!$D$26,",","."))) -> 7460 | G18: 13 | H18: =IFERROR(Hoja4!$D$14*1,VALUE(SUBSTITUTE(Hoja4!$D$14,",","."))) -> 10300 | I18: =IF(ISNUMBER(F18),F18/H18,"n.c.") -> 0.72427184
A19: Gel C (K2/K10 int) | B19: K2 | C19: 1 | D19: Sin dif | E19: 26 | F19: =IFERROR(Hoja4!$D$27*1,VALUE(SUBSTITUTE(Hoja4!$D$27,",","."))) -> 10000 | G19: 14 | H19: =IFERROR(Hoja4!$D$15*1,VALUE(SUBSTITUTE(Hoja4!$D$15,",","."))) -> 1440 | I19: =IF(ISNUMBER(F19),F19/H19,"n.c.") -> 6.9444444
A20: Gel C (K2/K10 int) | B20: K2 | C20: 2 | D20: Dif | E20: 27 | F20: =IFERROR(Hoja4!$D$28*1,VALUE(SUBSTITUTE(Hoja4!$D$28,",","."))) -> 8680 | G20: 15 | H20: =IFERROR(Hoja4!$D$16*1,VALUE(SUBSTITUTE(Hoja4!$D$16,",","."))) -> 11000 | I20: =IF(ISNUMBER(F20),F20/H20,"n.c.") -> 0.78909091
A21: Gel C (K2/K10 int) | B21: K2 | C21: 2 | D21: Sin dif | E21: 28 | F21: =IFERROR(Hoja4!$D$29*1,VALUE(SUBSTITUTE(Hoja4!$D$29,",","."))) -> 19200 | G21: 16 | H21: =IFERROR(Hoja4!$D$17*1,VALUE(SUBSTITUTE(Hoja4!$D$17,",","."))) -> 2180 | I21: =IF(ISNUMBER(F21),F21/H21,"n.c.") -> 8.8073394
A22: Gel C (K2/K10 int) | B22: K10 int | C22: 1 | D22: Dif | E22: — | F22: sin banda | G22: 17 | H22: =IFERROR(Hoja4!$D$18*1,VALUE(SUBSTITUTE(Hoja4!$D$18,",","."))) -> 6780 | I22: =IF(ISNUMBER(F22),F22/H22,"n.c.") -> n.c.
A23: Gel C (K2/K10 int) | B23: K10 int | C23: 1 | D23: Sin dif | E23: — | F23: sin banda | G23: 18 | H23: =IFERROR(Hoja4!$D$19*1,VALUE(SUBSTITUTE(Hoja4!$D$19,",","."))) -> 1640 | I23: =IF(ISNUMBER(F23),F23/H23,"n.c.") -> n.c.
A24: Gel D (K14/IVL) | B24: K14 | C24: 2 | D24: Dif | E24: 29 | F24: =IFERROR(Hoja4!$D$30*1,VALUE(SUBSTITUTE(Hoja4!$D$30,",","."))) -> 7640 | G24: 19 | H24: =IFERROR(Hoja4!$D$20*1,VALUE(SUBSTITUTE(Hoja4!$D$20,",","."))) -> 8200 | I24: =IF(ISNUMBER(F24),F24/H24,"n.c.") -> 0.93170732
A25: Gel D (K14/IVL) | B25: K14 | C25: 2 | D25: Sin dif | E25: 30 | F25: =IFERROR(Hoja4!$D$31*1,VALUE(SUBSTITUTE(Hoja4!$D$31,",","."))) -> 19400 | G25: 20 | H25: =IFERROR(Hoja4!$D$21*1,VALUE(SUBSTITUTE(Hoja4!$D$21,",","."))) -> 1490 | I25: =IF(ISNUMBER(F25),F25/H25,"n.c.") -> 13.020134
A26: Gel D (K14/IVL) | B26: IVL | C26: 1 | D26: Dif | E26: 31 | F26: =IFERROR(Hoja4!$D$32*1,VALUE(SUBSTITUTE(Hoja4!$D$32,",","."))) -> 18100 | G26: 21 | H26: =IFERROR(Hoja4!$D$22*1,VALUE(SUBSTITUTE(Hoja4!$D$22,",","."))) -> 7320 | I26: =IF(ISNUMBER(F26),F26/H26,"n.c.") -> 2.4726776
A27: Gel D (K14/IVL) | B27: IVL | C27: 1 | D27: Sin dif | E27: 46 | F27: =IFERROR(Hoja4!$D$47*1,VALUE(SUBSTITUTE(Hoja4!$D$47,",","."))) -> 57.6 | G27: 22 | H27: =IFERROR(Hoja4!$D$23*1,VALUE(SUBSTITUTE(Hoja4!$D$23,",","."))) -> 1670 | I27: =IF(ISNUMBER(F27),F27/H27,"n.c.") -> 0.034491018
A28: Gel D (K14/IVL) | B28: IVL | C28: 2 | D28: Dif | E28: 32 | F28: =IFERROR(Hoja4!$D$33*1,VALUE(SUBSTITUTE(Hoja4!$D$33,",","."))) -> 11300 | G28: 23 | H28: =IFERROR(Hoja4!$D$24*1,VALUE(SUBSTITUTE(Hoja4!$D$24,",","."))) -> 6760 | I28: =IF(ISNUMBER(F28),F28/H28,"n.c.") -> 1.6715976
A29: Gel D (K14/IVL) | B29: IVL | C29: 2 | D29: Sin dif | E29: 47 | F29: =IFERROR(Hoja4!$D$48*1,VALUE(SUBSTITUTE(Hoja4!$D$48,",","."))) -> -8 | G29: 24 | H29: =IFERROR(Hoja4!$D$25*1,VALUE(SUBSTITUTE(Hoja4!$D$25,",","."))) -> 1370 | I29: =IF(ISNUMBER(F29),F29/H29,"n.c.") -> -0.0058394161
A31: Por pareja (réplica)
A32: Anticuerpo | B32: Réplica | C32: Norm. Dif | D32: Norm. Sin dif | E32: Fold Dif / Sin dif (normalizado) | F32: log2 fold | G32: Fold Dif / Sin dif (señal bruta) | H32: 14-3-3ζ Dif / Sin dif
A33: K14 | B33: 1 | C33: =I6 -> 0.63099631 | D33: =I7 -> 16.788321 | E33: =IF(AND(ISNUMBER(F6),ISNUMBER(F7)),IF(F7<$G$3,IF(F6<$G$3,"no detectado","solo en Dif"),IF(F6<$G$3,"solo en Sin dif",C33/D33)),"no detectado") -> 0.037585432 | F33: =IF(ISNUMBER(E33),LOG(E33,2),"") -> -4.7336826 | G33: =IF(ISNUMBER(E33),F6/F7,"") -> 0.21242236 | H33: =H6/H7 -> 5.6517205
A34: K14 | B34: 2 | C34: =I24 -> 0.93170732 | D34: =I25 -> 13.020134 | E34: =IF(AND(ISNUMBER(F24),ISNUMBER(F25)),IF(F25<$G$3,IF(F24<$G$3,"no detectado","solo en Dif"),IF(F24<$G$3,"solo en Sin dif",C34/D34)),"no detectado") -> 0.071558964 | F34: =IF(ISNUMBER(E34),LOG(E34,2),"") -> -3.8047237 | G34: =IF(ISNUMBER(E34),F24/F25,"") -> 0.39381443 | H34: =H24/H25 -> 5.5033557
A35: K5 | B35: 1 | C35: =I8 -> 0.058006042 | D35: =I9 -> 3.1398601 | E35: =IF(AND(ISNUMBER(F8),ISNUMBER(F9)),IF(F9<$G$3,IF(F8<$G$3,"no detectado","solo en Dif"),IF(F8<$G$3,"solo en Sin dif",C35/D35)),"no detectado") -> 0.018474085 | F35: =IF(ISNUMBER(E35),LOG(E35,2),"") -> -5.7583533 | G35: =IF(ISNUMBER(E35),F8/F9,"") -> 0.085523385 | H35: =H8/H9 -> 4.6293706
A36: K5 | B36: 2 | C36: =I10 -> 0.038368247 | D36: =I11 -> 1.5748792 | E36: =IF(AND(ISNUMBER(F10),ISNUMBER(F11)),IF(F11<$G$3,IF(F10<$G$3,"no detectado","solo en Dif"),IF(F10<$G$3,"solo en Sin dif",C36/D36)),"no detectado") -> 0.02436266 | F36: =IF(ISNUMBER(E36),LOG(E36,2),"") -> -5.3591845 | G36: =IF(ISNUMBER(E36),F10/F11,"") -> 0.10674847 | H36: =H10/H11 -> 4.3816425
A37: K1 | B37: 1 | C37: =I12 -> 0.024594595 | D37: =I13 -> 1.2956522 | E37: =IF(AND(ISNUMBER(F12),ISNUMBER(F13)),IF(F13<$G$3,IF(F12<$G$3,"no detectado","solo en Dif"),IF(F12<$G$3,"solo en Sin dif",C37/D37)),"no detectado") -> 0.018982405 | F37: =IF(ISNUMBER(E37),LOG(E37,2),"") -> -5.7191934 | G37: =IF(ISNUMBER(E37),F12/F13,"") -> 0.18322148 | H37: =H12/H13 -> 9.6521739
A38: K1 | B38: 2 | C38: =I14 -> 0.01849866 | D38: =I15 -> 0.74534161 | E38: =IF(AND(ISNUMBER(F14),ISNUMBER(F15)),IF(F15<$G$3,IF(F14<$G$3,"no detectado","solo en Dif"),IF(F14<$G$3,"solo en Sin dif",C38/D38)),"no detectado") -> 0.024819035 | F38: =IF(ISNUMBER(E38),LOG(E38,2),"") -> -5.3324092 | G38: =IF(ISNUMBER(E38),F14/F15,"") -> 0.115 | H38: =H14/H15 -> 4.6335404
A39: K2 | B39: 1 | C39: =I18 -> 0.72427184 | D39: =I19 -> 6.9444444 | E39: =IF(AND(ISNUMBER(F18),ISNUMBER(F19)),IF(F19<$G$3,IF(F18<$G$3,"no detectado","solo en Dif"),IF(F18<$G$3,"solo en Sin dif",C39/D39)),"no detectado") -> 0.10429515 | F39: =IF(ISNUMBER(E39),LOG(E39,2),"") -> -3.2612561 | G39: =IF(ISNUMBER(E39),F18/F19,"") -> 0.746 | H39: =H18/H19 -> 7.1527778
A40: K2 | B40: 2 | C40: =I20 -> 0.78909091 | D40: =I21 -> 8.8073394 | E40: =IF(AND(ISNUMBER(F20),ISNUMBER(F21)),IF(F21<$G$3,IF(F20<$G$3,"no detectado","solo en Dif"),IF(F20<$G$3,"solo en Sin dif",C40/D40)),"no detectado") -> 0.089594697 | F40: =IF(ISNUMBER(E40),LOG(E40,2),"") -> -3.4804428 | G40: =IF(ISNUMBER(E40),F20/F21,"") -> 0.45208333 | H40: =H20/H21 -> 5.0458716
A41: K10 ab | B41: 1 | C41: =I16 -> 0.41719343 | D41: =I17 -> 0.0017560976 | E41: =IF(AND(ISNUMBER(F16),ISNUMBER(F17)),IF(F17<$G$3,IF(F16<$G$3,"no detectado","solo en Dif"),IF(F16<$G$3,"solo en Sin dif",C41/D41)),"no detectado") -> solo en Dif | F41: =IF(ISNUMBER(E41),LOG(E41,2),"") | G41: =IF(ISNUMBER(E41),F16/F17,"") | H41: =H16/H17 -> 3.8585366
A42: K10 int | B42: 1 | C42: =I22 -> n.c. | D42: =I23 -> n.c. | E42: =IF(AND(ISNUMBER(F22),ISNUMBER(F23)),IF(F23<$G$3,IF(F22<$G$3,"no detectado","solo en Dif"),IF(F22<$G$3,"solo en Sin dif",C42/D42)),"no detectado") -> no detectado | F42: =IF(ISNUMBER(E42),LOG(E42,2),"") | G42: =IF(ISNUMBER(E42),F22/F23,"") | H42: =H22/H23 -> 4.1341463
...

Sheet Graficas
A1: Diana / 14-3-3ζ (media de parejas): Diferenciada vs Sin diferenciar

Sheet ARNm vs proteina
A1: MD2: ARNm (qPCR, 7 d vs 0 d) frente a proteína (WB, Dif vs Sin dif)
A2: ARNm: RQ 2^-ΔΔCt con YWHAZ, de qPCR_analisis_MD2_MD3.xlsx (hoja Resumen; azul = copiado de ese archivo). Proteína: fold de la hoja Analisis (fórmulas).
A3: Supuesto: WB «Sin dif» = KerCT WT / 0 días y «Dif» = KerCT MD2 7 días (Hoja1). Fold > 1 = más en diferenciado.
K4: K10 e IVL: la barra de proteína es un mínimo (en Sin dif no hay banda).
A5: Gen | B5: ARNm MD2 rep 1 | C5: ARNm MD2 rep 2 | D5: ARNm 7d/0d (media) | E5: Proteína Dif/Sin dif (norm. 14-3-3ζ) | F5: Proteína Dif/Sin dif (señal bruta) | G5: ¿Proteína es un mínimo? | H5: ¿Mismo sentido ARNm y proteína? | I5: Comentario
A6: KRT1 / K1 | B6: 68.645 | C6: 43.27 | D6: =10^AVERAGE(LOG(B6),LOG(C6)) -> 54.500176 | E6: =Analisis!C51 -> 0.021705414 | F6: =10^AVERAGE(LOG(Analisis!G37),LOG(Analisis!G38)) -> 0.14515671 | G6: No | H6: =IF(SIGN(LOG(D6))=SIGN(LOG(E6)),"Sí","NO") -> NO | I6: ARNm casi ausente a 0 d (Ct ≈ 32) pero el WB da banda fuerte en Sin dif: la banda probablemente no es K1 (reacción cruzada).
A7: KRT2 / K2 | B7: 2.486 | C7: 2.235 | D7: =10^AVERAGE(LOG(B7),LOG(C7)) -> 2.3571614 | E7: =Analisis!C50 -> 0.096665878 | F7: =10^AVERAGE(LOG(Analisis!G39),LOG(Analisis!G40)) -> 0.58073588 | G7: No | H7: =IF(SIGN(LOG(D7))=SIGN(LOG(E7)),"Sí","NO") -> NO | I7: ARNm muy bajo en ambas (Ct ≈ 30–31): la banda fuerte en Sin dif del WB es sospechosa.
A8: KRT10 / K10 (ab) | B8: 24.548 | C8: 21.124 | D8: =10^AVERAGE(LOG(B8),LOG(C8)) -> 22.771736 | E8: =(Analisis!I16/(Analisis!$G$3/Analisis!H17)) -> 8.5524652 | F8: =(Analisis!F16/Analisis!$G$3) -> 33 | G8: Sí (≥) | H8: =IF(SIGN(LOG(D8))=SIGN(LOG(E8)),"Sí","NO") -> Sí | I8: Concuerdan: K10 solo detectable en Dif. El valor de proteína es un mínimo (Sin dif bajo el límite de detección).
A9: KRT14 / K14 | B9: 0.351 | C9: 0.414 | D9: =10^AVERAGE(LOG(B9),LOG(C9)) -> 0.38120073 | E9: =Analisis!C48 -> 0.051861109 | F9: =10^AVERAGE(LOG(Analisis!G33),LOG(Analisis!G34)) -> 0.28923173 | G9: No | H9: =IF(SIGN(LOG(D9))=SIGN(LOG(E9)),"Sí","NO") -> Sí | I9: Concuerdan (bajan). La proteína sin normalizar (~0,3) se parece mucho al ARNm (~0,4); normalizada a 14-3-3ζ se exagera.
A10: IVL | B10: 177.766 | C10: 162.138 | D10: =10^AVERAGE(LOG(B10),LOG(C10)) -> 169.77227 | E10: =10^AVERAGE(LOG(Analisis!I26/(Analisis!$G$3/Analisis!H27)),LOG(Analisis!I28/(Analisis!$G$3/Analisis!H29))) -> 30.75163 | F10: =10^AVERAGE(LOG(Analisis!F26/Analisis!$G$3),LOG(Analisis!F28/Analisis!$G$3)) -> 143.01399 | G10: Sí (≥) | H10: =IF(SIGN(LOG(D10))=SIGN(LOG(E10)),"Sí","NO") -> Sí | I10: Concuerdan: IVL solo detectable en Dif. Valor de proteína = mínimo.
A11: KRT5 / K5 | B11: no medido | E11: =Analisis!C49 -> 0.021215038 | F11: =10^AVERAGE(LOG(Analisis!G35),LOG(Analisis!G36)) -> 0.095548366 | I11: Sin dato de ARNm en MD2 (en Medio 3D sí). Proteína baja con la diferenciación, como se espera.
A12: La media de ARNm es geométrica entre MD2 rep 1 y rep 2. En proteína: media geométrica de las parejas del WB.
A14: Lectura:
A15: • K14, K10 e IVL: ARNm y proteína van en el mismo sentido (K14 baja; K10 e IVL suben, y en proteína solo aparecen en diferenciado).
A16: • K1 y K2: discrepancia total. El ARNm sube con la diferenciación (K1 ~56×, K2 ~2,4×) pero el WB da más señal en Sin dif, incluso sin normalizar.
A17: A 0 d el ARNm de KRT1 y KRT2 está casi en el límite (Ct 30–32), así que una banda fuerte en Sin dif no es creíble: revisar especificidad del anticuerpo / altura de la banda (K1 ~67 kDa, K2 ~65 kDa; K5 ~58 kDa, K14 ~50 kDa).
A18: • 14-3-3ζ (YWHAZ): el ARNm apenas cambia (Ct 16,4 a 0 d frente a 16,0 a 7 d en MD2, ~1,3×), pero la proteína sale 4–8× más alta en Dif con la misma carga teórica (30 µg).
A19: Eso apunta a carga desigual / cuantificación de proteína, más que a un cambio real de 14-3-3ζ. Con señal sin normalizar, K14 (0,3×) coincide con el ARNm (0,4×).
A20: • Magnitudes: no son comparables 1:1 (el WB satura y tiene menos rango dinámico que la qPCR); lo comparable es el sentido del cambio.

Sheet Hoja1
A1: Condición | B1: Concentración | C1: ul para 30ng | D1: ul agente reductor | E1: ul tampón carga | F1: ul H2O | G1: volumen final | H1: ¿Cuántas?
A2: KerCT WT | B2: 4.085 | C2: =30/B2 -> 7.3439412 | D2: =G2/10 -> 1.5 | E2: =G2/4 -> 3.75 | F2: =G2-C2-E2 -> 3.9060588 | G2: 15 | H2: 12
A3: KerCT MD2 7 días | B3: 13.8 | C3: =30/B3 -> 2.173913 | D3: =G3/10 -> 1.5 | E3: =G3/4 -> 3.75 | F3: =G3-C3-E3 -> 9.076087 | G3: 15 | H3: 12
G38: 1:5000 el de K10 abcam al final

Sheet Hoja2

Sheet Hoja3

Sheet Hoja4
A1: Image Name | B1: Channel | C1: Name | D1: Signal | E1: Total | F1: Area | G1: Bkgnd. | H1: Type
A2: 3461 | B2: 685Ex-720Em | C2: 1 | D2: 5420 | E2: 6400 | F2: 3072 | G2: 0,316 | H2: Signal
A3: 3461 | B3: 685Ex-720Em | C3: 2 | D3: 959 | E3: 1840 | F3: 3072 | G3: 0,286 | H3: Signal
A4: 3461 | B4: 685Ex-720Em | C4: 3 | D4: 6620 | E4: 7480 | F4: 3072 | G4: 0,281 | H4: Signal
A5: 3461 | B5: 685Ex-720Em | C5: 4 | D5: 1430 | E5: 2080 | F5: 2310 | G5: 0,284 | H5: Signal
A6: 3461 | B6: 685Ex-720Em | C6: 5 | D6: 9070 | E6: 10000 | F6: 3072 | G6: 0,314 | H6: Signal
A7: 3461 | B7: 685Ex-720Em | C7: 6 | D7: 2070 | E7: 2710 | F7: 2250 | G7: 0,281 | H7: Signal
A8: 3461 | B8: 685Ex-720Em | C8: 7 | D8: 11100 | E8: 12100 | F8: 3384 | G8: 0,286 | H8: Signal
A9: 3461 | B9: 685Ex-720Em | C9: 8 | D9: 1150 | E9: 1790 | F9: 2250 | G9: 0,283 | H9: Signal
A10: 3461 | B10: 685Ex-720Em | C10: 9 | D10: 7460 | E10: 8220 | F10: 2560 | G10: 0,295 | H10: Signal
A11: 3461 | B11: 685Ex-720Em | C11: 10 | D11: 1610 | E11: 2320 | F11: 2560 | G11: 0,279 | H11: Signal
A12: 3461 | B12: 685Ex-720Em | C12: 11 | D12: 7910 | E12: 8730 | F12: 2656 | G12: 0,309 | H12: Signal
A13: 3461 | B13: 685Ex-720Em | C13: 12 | D13: 2050 | E13: 2740 | F13: 2560 | G13: 0,271 | H13: Signal
... A45: 3461 | B45: 785Ex-820Em | C45: 44 | D45: 1200 | E45: 1390 | F45: 2844 | G45: 0,0666 | H45: Signal
A46: 3461 | B46: 785Ex-820Em | C46: 45 | D46: 3,60 | E46: 63,4 | F46: 2844 | G46: 0,0210 | H46: Signal
A47: 3461 | B47: 785Ex-820Em | C47: 46 | D47: 57,6 | E47: 570 | F47: 2844 | G47: 0,180 | H47: Signal
A48: 3461 | B48: 785Ex-820Em | C48: 47 | D48: -8,00 | E48: 406 | F48: 2844 | G48: 0,146 | H48: Signal
